<?xml version='1.0'?>
<robot xmlns:xacro="http://www.ros.org/wiki/xacro" >	

    <xacro:include filename="inertial_macros.xacro"/>


    <xacro:property name="chassis_length" value="0.405"/>
    <xacro:property name="chassis_width" value="0.405"/>
    <xacro:property name="chassis_height" value="0.01"/>
    <xacro:property name="chassis_mass" value="1.0"/>
    <xacro:property name="wheel_radius" value="0.0625"/>
    <xacro:property name="wheel_thickness" value="0.030"/>
    <xacro:property name="wheel_mass" value="0.05"/>
    <xacro:property name="wheel_offset_x" value="0.025"/>
    <xacro:property name="wheel_offset_y" value="0.2225"/>
    <xacro:property name="wheel_offset_z" value="-0.025"/>
    <xacro:property name="caster_wheel_radius" value="0.02"/>
    <xacro:property name="caster_wheel_mass" value="0.01"/>
    <xacro:property name="caster_wheel_offset_x" value="0.475"/>
    <xacro:property name="caster_wheel_offset_y" value="0.2225"/>
    <xacro:property name="caster_wheel_offset_z" value="${wheel_offset_z - wheel_radius + caster_wheel_radius}"/>

    <xacro:property name="link_0_radius" value="0.08"/>
    <xacro:property name="link_0_height" value="0.062"/>

    <xacro:property name="link_1_radius" value="0.08"/>
    <xacro:property name="link_1_height" value="0.1655"/>

    <xacro:property name="link_2_width" value="0.1346"/>
    <xacro:property name="link_2_length" value="0.1346"/>
    <xacro:property name="link_2_height" value="0.2202"/>

    <xacro:property name="link_3_width" value="0.0776"/>
    <xacro:property name="link_3_length" value="0.095"/>
    <xacro:property name="link_3_height" value="0.1299"/>

    <xacro:property name="link_4_width" value="0.0719"/>
    <xacro:property name="link_4_length" value="0.0891"/>
    <xacro:property name="link_4_height" value="0.0949"/>

    <xacro:property name="link_5_width" value="0.048"/>
    <xacro:property name="link_5_length" value="0.0700"/>
    <xacro:property name="link_5_height" value="0.0510"/>

    <xacro:property name="hand_width" value="0.049"/>
    <xacro:property name="hand_length" value="0.0632"/>
    <xacro:property name="hand_height" value="0.0490"/>

    <xacro:property name="gripper_servo_gear_width" value="0.006"/>
    <xacro:property name="gripper_servo_gear_length" value="0.006"/>
    <xacro:property name="gripper_servo_gear_height" value="0.0399"/>

    <xacro:property name="tip_gripper_servo_width" value="0.018"/>
    <xacro:property name="tip_gripper_servo_length" value="0.021"/>
    <xacro:property name="tip_gripper_servo_height" value="0.07"/>

    <xacro:property name="pivot_arm_gripper_servo_width" value="0.006"/>
    <xacro:property name="pivot_arm_gripper_servo_length" value="0.006"/>
    <xacro:property name="pivot_arm_gripper_servo_height" value="0.0399"/>

    <xacro:property name="gripper_idol_gear_width" value="0.006"/>
    <xacro:property name="gripper_idol_gear_length" value="0.006"/>
    <xacro:property name="gripper_idol_gear_height" value="0.0399"/>

    <xacro:property name="tip_gripper_idol_width" value="0.018"/>
    <xacro:property name="tip_gripper_idol_length" value="0.021"/>
    <xacro:property name="tip_gripper_idol_height" value="0.07"/>

    <xacro:property name="pivot_arm_gripper_idol_width" value="0.006"/>
    <xacro:property name="pivot_arm_gripper_idol_length" value="0.006"/>
    <xacro:property name="pivot_arm_gripper_idol_height" value="0.0399"/>

    <material name="white">
        <color rgba="1 1 1 1" />
    </material>

    <material name="orange">
        <color rgba="1 0.3 0.1 1"/>
    </material>

    <material name="blue">
        <color rgba="0.2 0.2 1 1"/>
    </material>

    <material name="black">
        <color rgba="0 0 0 1"/>
    </material>

    <material name="red">
        <color rgba="1 0 0 1"/>
    </material>

    <!-- BASE LINK -->

    <link name="base_link"></link>
    <!-- BASE_FOOTPRINT LINK -->

    <joint name="base_footprint_joint" type="fixed">
        <parent link="base_link"/>
        <child link="base_footprint"/>
        <origin xyz="0 0 0" rpy="0 0 0"/>
    </joint>

    <link name="base_footprint">
    </link>

    <!-- <link name="odom"></link>
    <joint name="odom_joint" type="fixed">
        <parent link="base_link"/>
        <child link="odom"/>
        <origin xyz="0 0 0"/>
    </joint> -->

    <!-- BASE LINK -->

    <joint name="floor_joint" type="fixed">
        <parent link="base_link"/>
        <child link="floor"/>
        <origin xyz="0 0 ${wheel_radius}"/>
    </joint>

    <link name="floor"></link>
    <!-- BASE_FOOTPRINT LINK -->

    <!-- <joint name="base_footprint_joint" type="fixed">
        <parent link="floor"/>
        <child link="base_footprint"/>
        <origin xyz="0 0 0" rpy="0 0 0"/>
    </joint>

    <link name="base_footprint">
    </link> -->


    <!-- CHASSIS LINK -->

    <joint name="chassis_joint" type="fixed">
        <parent link="floor"/>
        <child link="chassis"/>
        <origin xyz="${-wheel_offset_x} 0 ${-wheel_offset_z}"/>
    </joint>

    <link name="chassis">
        <visual>
            <origin xyz="${chassis_length/2} 0 ${chassis_height/2}"/>
            <geometry>
                <box size="${chassis_length} ${chassis_width} ${chassis_height}"/>
            </geometry>
            <material name="orange"/>
        </visual>
        <collision>
            <origin xyz="${chassis_length/2} 0 ${chassis_height/2}"/>
            <geometry>
                <box size="${chassis_length} ${chassis_width} ${chassis_height}"/>
            </geometry>
        </collision>
        <xacro:inertial_box mass="10.0" x="${chassis_length}" y="${chassis_width}" z="${chassis_height}">
            <origin xyz="${chassis_length/2} 0 ${chassis_height/2}" rpy="0 0 0"/>
        </xacro:inertial_box>
    </link>

    <!-- LEFT WHEEL LINK -->

    <joint name="left_wheel_joint" type="continuous">
        <parent link="floor"/>
        <child link="left_wheel"/>
        <origin xyz="0 ${wheel_offset_y} 0" rpy="-${pi/2} 0 0" />
        <axis xyz="0 0 1"/>
        <!-- <dynamics damping="10.0" friction="10.0"/> -->
    </joint>

    <link name="left_wheel">
        <visual>
            <geometry>
                <cylinder radius="${wheel_radius}" length="${wheel_thickness}"/>
            </geometry>
            <material name="blue"/>
        </visual>
        <collision>
            <geometry>
                <sphere radius="${wheel_radius}"/>
            </geometry>
        </collision>
        <xacro:inertial_cylinder mass="${wheel_mass}" length="${wheel_thickness}" radius="${wheel_radius}">
            <origin xyz="0 0 0" rpy="0 0 0"/>
        </xacro:inertial_cylinder>
    </link>

    <!-- RIGHT WHEEL LINK -->

    <joint name="right_wheel_joint" type="continuous">
        <parent link="floor"/>
        <child link="right_wheel"/>
        <origin xyz="0 ${-wheel_offset_y} 0" rpy="${pi/2} 0 0" />
        <axis xyz="0 0 -1"/>
        <!-- <dynamics damping="10.0" friction="10.0"/> -->
    </joint>

    <link name="right_wheel">
        <visual>
            <geometry>
                <cylinder radius="${wheel_radius}" length="${wheel_thickness}"/>
            </geometry>
            <material name="blue"/>
        </visual>
        <collision>
            <geometry>
                <sphere radius="${wheel_radius}"/>
            </geometry>
        </collision>
        <xacro:inertial_cylinder mass="${wheel_mass}" length="${wheel_thickness}" radius="${wheel_radius}">
            <origin xyz="0 0 0" rpy="0 0 0"/>
        </xacro:inertial_cylinder>
    </link>

    <!-- CASTER WHEEL LINK -->

    <joint name="caster_wheel_joint" type="fixed">
        <parent link="chassis"/>
        <child link="caster_wheel"/>
        <origin xyz="${caster_wheel_offset_x} ${caster_wheel_offset_y} ${caster_wheel_offset_z}"/>
    </joint>


    <link name="caster_wheel">
        <visual>
            <geometry>
                <sphere radius="${caster_wheel_radius}"/>
            </geometry>
            <material name="white"/>
        </visual>
        <collision>
            <geometry>
                <sphere radius="${caster_wheel_radius}"/>
            </geometry>
        </collision>
        <xacro:inertial_sphere mass="${caster_wheel_mass}" radius="${caster_wheel_radius}">
            <origin xyz="0 0 0" rpy="0 0 0"/>
        </xacro:inertial_sphere>
    </link>

    <joint name="caster_wheel_joint2" type="fixed">
        <parent link="chassis"/>
        <child link="caster_wheel2"/>
        <origin xyz="${caster_wheel_offset_x} ${-caster_wheel_offset_y} ${caster_wheel_offset_z}"/>
    </joint>

    <link name="caster_wheel2">
        <visual>
            <geometry>
                <sphere radius="${caster_wheel_radius}"/>
            </geometry>
            <material name="white"/>
        </visual>
        <collision>
            <geometry>
                <sphere radius="${caster_wheel_radius}"/>
            </geometry>
        </collision>
        <xacro:inertial_sphere mass="${caster_wheel_mass}" radius="${caster_wheel_radius}">
            <origin xyz="0 0 0" rpy="0 0 0"/>
        </xacro:inertial_sphere>
    </link>

  <gazebo reference="chassis">
      <gravity>1</gravity>
      <material>Gazebo/Orange</material>
  </gazebo>

  <gazebo reference="left_wheel">
      <gravity>1</gravity>
      <material>Gazebo/Blue</material>
  </gazebo>

  <gazebo reference="right_wheel">
      <gravity>1</gravity>
      <material>Gazebo/Blue</material>
  </gazebo>

  <gazebo reference="caster_wheel">
      <gravity>1</gravity>
      <material>Gazebo/White</material>
      <mu1 value="0.001"/>
      <mu2 value="0.001"/>
  </gazebo>

  <gazebo reference="caster_wheel2">
      <gravity>1</gravity>
      <material>Gazebo/White</material>
      <mu1 value="0.001"/>
      <mu2 value="0.001"/>
  </gazebo>


</robot>


  
