<sdf version='1.9'>
  <model name='robot_description'>
    <link name='base_link'>
      <inertial>
        <pose>0.1780559729414199 -1.243941050198591e-05 0.4466954508265594 0 0 0</pose>
        <mass>10.021246584</mass>
        <inertia>
          <ixx>0.57353490040801036</ixx>
          <ixy>1.20848873026793e-05</ixy>
          <ixz>0.0022778695219971561</ixz>
          <iyy>0.57402618883127721</iyy>
          <iyz>4.8841728212682492e-05</iyz>
          <izz>0.27587865607071232</izz>
        </inertia>
      </inertial>
      <collision name='base_link_fixed_joint_lump__chassis_collision'>
        <pose>0.1775 0 0.4475 0 0 0</pose>
        <geometry>
          <box>
            <size>0.405 0.405 0.72</size>
          </box>
        </geometry>
      </collision>
      <collision name='base_link_fixed_joint_lump__caster_wheel_collision_1'>
        <pose>0.45 0.2225 0.02000000000000001 0 0 0</pose>
        <geometry>
          <sphere>
            <radius>0.02</radius>
          </sphere>
        </geometry>
      </collision>
      <collision name='base_link_fixed_joint_lump__caster_wheel2_collision_2'>
        <pose>0.45 -0.2225 0.02000000000000001 0 0 0</pose>
        <geometry>
          <sphere>
            <radius>0.02</radius>
          </sphere>
        </geometry>
      </collision>
      <collision name='base_link_fixed_joint_lump__robot_link0_collision_3'>
        <pose>0.275 -0.1 0.8385 0 0 0</pose>
        <geometry>
          <cylinder>
            <length>0.062</length>
            <radius>0.080000000000000002</radius>
          </cylinder>
        </geometry>
      </collision>
      <visual name='base_link_fixed_joint_lump__chassis_visual'>
        <pose>0.1775 0 0.4475 0 0 0</pose>
        <geometry>
          <box>
            <size>0.405 0.405 0.72</size>
          </box>
        </geometry>
        <material>
          <diffuse>1 0.375 0.125 1</diffuse>
          <ambient>1 0.375 0.125 1</ambient>
        </material>
      </visual>
      <visual name='base_link_fixed_joint_lump__caster_wheel_visual_1'>
        <pose>0.45 0.2225 0.02000000000000001 0 0 0</pose>
        <geometry>
          <sphere>
            <radius>0.02</radius>
          </sphere>
        </geometry>
        <material>
          <diffuse>1 1 1 1</diffuse>
          <ambient>1 1 1 1</ambient>
        </material>
      </visual>
      <visual name='base_link_fixed_joint_lump__caster_wheel2_visual_2'>
        <pose>0.45 -0.2225 0.02000000000000001 0 0 0</pose>
        <geometry>
          <sphere>
            <radius>0.02</radius>
          </sphere>
        </geometry>
        <material>
          <diffuse>1 1 1 1</diffuse>
          <ambient>1 1 1 1</ambient>
        </material>
      </visual>
      <visual name='base_link_fixed_joint_lump__robot_link0_visual_3'>
        <pose>0.275 -0.1 0.8385 0 0 0</pose>
        <geometry>
          <cylinder>
            <length>0.062</length>
            <radius>0.080000000000000002</radius>
          </cylinder>
        </geometry>
        <material>
          <diffuse>0.941175 0.941175 0.941175 1</diffuse>
          <ambient>0.941175 0.941175 0.941175 1</ambient>
        </material>
      </visual>
    </link>
    <joint name='left_wheel_joint' type='revolute'>
      <pose relative_to='base_link'>0 0.2225 0.0625 -1.570796326794896 0 0</pose>
      <parent>base_link</parent>
      <child>left_wheel</child>
      <axis>
        <xyz>0 0 1</xyz>
        <limit>
          <lower>-10000000000000000</lower>
          <upper>10000000000000000</upper>
        </limit>
        <dynamics>
          <spring_reference>0</spring_reference>
          <spring_stiffness>0</spring_stiffness>
          <damping>21.75</damping>
          <friction>3.48</friction>          
        </dynamics>
      </axis>
    </joint>
    <link name='left_wheel'>
      <pose relative_to='left_wheel_joint'>0 0 0 0 0 0</pose>
      <inertial>
        <pose>0 0 0 0 0 0</pose>
        <mass>0.050000000000000003</mass>
        <inertia>
          <ixx>5.2578124999999999e-05</ixx>
          <ixy>0</ixy>
          <ixz>0</ixz>
          <iyy>5.2578124999999999e-05</iyy>
          <iyz>0</iyz>
          <izz>9.7656250000000005e-05</izz>
        </inertia>
      </inertial>
      <collision name='left_wheel_collision'>
        <pose>0 0 0 0 0 0</pose>
        <geometry>
          <sphere>
            <radius>0.0625</radius>
          </sphere>
        </geometry>
      </collision>
      <visual name='left_wheel_visual'>
        <pose>0 0 0 0 0 0</pose>
        <geometry>
          <cylinder>
            <length>0.029999999999999999</length>
            <radius>0.0625</radius>
          </cylinder>
        </geometry>
        <material>
          <diffuse>0.25 0.25 1 1</diffuse>
          <ambient>0.25 0.25 1 1</ambient>
        </material>
      </visual>
    </link>
    <joint name='right_wheel_joint' type='revolute'>
      <pose relative_to='base_link'>0 -0.2225 0.0625 1.570796326794896 0 0</pose>
      <parent>base_link</parent>
      <child>right_wheel</child>
      <axis>
        <xyz>0 0 -1</xyz>
        <limit>
          <lower>-10000000000000000</lower>
          <upper>10000000000000000</upper>
        </limit>
        <dynamics>
          <spring_reference>0</spring_reference>
          <spring_stiffness>0</spring_stiffness>
          <damping>21.75</damping>
          <friction>3.48</friction>          
        </dynamics>
      </axis>
    </joint>
    <link name='right_wheel'>
      <pose relative_to='right_wheel_joint'>0 0 0 0 0 0</pose>
      <inertial>
        <pose>0 0 0 0 0 0</pose>
        <mass>0.050000000000000003</mass>
        <inertia>
          <ixx>5.2578124999999999e-05</ixx>
          <ixy>0</ixy>
          <ixz>0</ixz>
          <iyy>5.2578124999999999e-05</iyy>
          <iyz>0</iyz>
          <izz>9.7656250000000005e-05</izz>
        </inertia>
      </inertial>
      <collision name='right_wheel_collision'>
        <pose>0 0 0 0 0 0</pose>
        <geometry>
          <sphere>
            <radius>0.0625</radius>
          </sphere>
        </geometry>
      </collision>
      <visual name='right_wheel_visual'>
        <pose>0 0 0 0 0 0</pose>
        <geometry>
          <cylinder>
            <length>0.029999999999999999</length>
            <radius>0.0625</radius>
          </cylinder>
        </geometry>
        <material>
          <diffuse>0.25 0.25 1 1</diffuse>
          <ambient>0.25 0.25 1 1</ambient>
        </material>
      </visual>
    </link>
    <frame name='base_footprint_joint' attached_to='base_link'>
      <pose>0 0 0 0 -0 0</pose>
    </frame>
    <frame name='base_footprint' attached_to='base_footprint_joint'/>
    <frame name='caster_wheel_joint' attached_to='chassis'>
      <pose>0.475 0.2225 -0.0675 0 -0 0</pose>
    </frame>
    <frame name='caster_wheel' attached_to='caster_wheel_joint'/>
    <frame name='caster_wheel_joint2' attached_to='chassis'>
      <pose>0.475 -0.2225 -0.0675 0 -0 0</pose>
    </frame>
    <frame name='caster_wheel2' attached_to='caster_wheel_joint2'/>
    <frame name='robot_joint0' attached_to='chassis'>
      <pose>0.3 -0.1 0.72 0 -0 0</pose>
    </frame>
    <frame name='robot_link0' attached_to='robot_joint0'/>
    <frame name='chassis_joint' attached_to='floor'>
      <pose>-0.025 0 0.025 0 -0 0</pose>
    </frame>
    <frame name='chassis' attached_to='chassis_joint'/>
    <frame name='floor_joint' attached_to='base_link'>
      <pose>0 0 0.0625 0 -0 0</pose>
    </frame>
    <frame name='floor' attached_to='floor_joint'/>
  </model>
</sdf>
