<?xml version="1.0" ?>
<!-- =================================================================================== -->
<!-- |    This document was autogenerated by xacro from robot_ignition.xacro           | -->
<!-- |    EDITING THIS FILE BY HAND IS NOT RECOMMENDED                                 | -->
<!-- =================================================================================== -->
<robot name="robot_description">
  <!-- Specify some standard inertial calculations https://en.wikipedia.org/wiki/List_of_moments_of_inertia -->
  <!-- These make use of xacro's mathematical functionality -->
  <material name="white">
    <color rgba="1 1 1 1"/>
  </material>
  <material name="orange">
    <color rgba="1 0.3 0.1 1"/>
  </material>
  <material name="blue">
    <color rgba="0.2 0.2 1 1"/>
  </material>
  <material name="black">
    <color rgba="0 0 0 1"/>
  </material>
  <material name="red">
    <color rgba="1 0 0 1"/>
  </material>
  <!-- BASE LINK -->
  <link name="base_link"/>
  <!-- BASE_FOOTPRINT LINK -->
  <joint name="base_footprint_joint" type="fixed">
    <parent link="base_link"/>
    <child link="base_footprint"/>
    <origin rpy="0 0 0" xyz="0 0 0"/>
  </joint>
  <link name="base_footprint">
    </link>
  <!-- <link name="odom"></link>
    <joint name="odom_joint" type="fixed">
        <parent link="base_link"/>
        <child link="odom"/>
        <origin xyz="0 0 0"/>
    </joint> -->
  <!-- BASE LINK -->
  <joint name="floor_joint" type="fixed">
    <parent link="base_link"/>
    <child link="floor"/>
    <origin xyz="0 0 0.0625"/>
  </joint>
  <link name="floor"/>
  <!-- BASE_FOOTPRINT LINK -->
  <!-- <joint name="base_footprint_joint" type="fixed">
        <parent link="floor"/>
        <child link="base_footprint"/>
        <origin xyz="0 0 0" rpy="0 0 0"/>
    </joint>

    <link name="base_footprint">
    </link> -->
  <!-- CHASSIS LINK -->
  <joint name="chassis_joint" type="fixed">
    <parent link="floor"/>
    <child link="chassis"/>
    <origin xyz="-0.025 0 0.025"/>
  </joint>
  <link name="chassis">
    <visual>
      <origin xyz="0.2025 0 0.36"/>
      <geometry>
        <box size="0.405 0.405 0.72"/>
      </geometry>
      <material name="orange"/>
    </visual>
    <collision>
      <origin xyz="0.2025 0 0.36"/>
      <geometry>
        <box size="0.405 0.405 0.72"/>
      </geometry>
    </collision>
    <inertial>
      <origin rpy="0 0 0" xyz="0.2025 0 0.36"/>
      <mass value="10.0"/>
      <inertia ixx="0.5686875" ixy="0.0" ixz="0.0" iyy="0.5686875" iyz="0.0" izz="0.27337500000000003"/>
    </inertial>
  </link>
  <!-- LEFT WHEEL LINK -->
  <joint name="left_wheel_joint" type="continuous">
    <parent link="floor"/>
    <child link="left_wheel"/>
    <origin rpy="-1.5707963267948966 0 0" xyz="0 0.2225 0"/>
    <axis xyz="0 0 1"/>
    <dynamics damping="21.75" friction="10.48" spring_reference="0" spring_stiffness="{joint_spring_stiffness}"/>
  </joint>
  <link name="left_wheel">
    <visual>
      <geometry>
        <cylinder length="0.03" radius="0.0625"/>
      </geometry>
      <material name="blue"/>
    </visual>
    <collision>
      <geometry>
        <sphere radius="0.0625"/>
      </geometry>
    </collision>
    <inertial>
      <origin rpy="0 0 0" xyz="0 0 0"/>
      <mass value="0.05"/>
      <inertia ixx="5.2578125e-05" ixy="0.0" ixz="0.0" iyy="5.2578125e-05" iyz="0.0" izz="9.765625e-05"/>
    </inertial>
  </link>
  <!-- RIGHT WHEEL LINK -->
  <joint name="right_wheel_joint" type="continuous">
    <parent link="floor"/>
    <child link="right_wheel"/>
    <origin rpy="1.5707963267948966 0 0" xyz="0 -0.2225 0"/>
    <axis xyz="0 0 -1"/>
    <dynamics damping="21.75" friction="10.48" spring_reference="0" spring_stiffness="{joint_spring_stiffness}"/>
  </joint>
  <link name="right_wheel">
    <visual>
      <geometry>
        <cylinder length="0.03" radius="0.0625"/>
      </geometry>
      <material name="blue"/>
    </visual>
    <collision>
      <geometry>
        <sphere radius="0.0625"/>
      </geometry>
    </collision>
    <inertial>
      <origin rpy="0 0 0" xyz="0 0 0"/>
      <mass value="0.05"/>
      <inertia ixx="5.2578125e-05" ixy="0.0" ixz="0.0" iyy="5.2578125e-05" iyz="0.0" izz="9.765625e-05"/>
    </inertial>
  </link>
  <!-- CASTER WHEEL LINK -->
  <joint name="caster_wheel_joint" type="revolute">
    <parent link="chassis"/>
    <child link="caster_wheel"/>
    <origin xyz="0.475 0.2225 -0.06749999999999999"/>
    <axis xyz="0 0 1"/>
    <limit effort="100" lower="-1.5707963267948966" upper="1.5707963267948966" velocity="100"/>
    <dynamics damping="21.75" friction="10.48" spring_reference="0" spring_stiffness="{joint_spring_stiffness}"/>
  </joint>
  <link name="caster_wheel">
    <visual>
      <geometry>
        <sphere radius="0.02"/>
      </geometry>
      <material name="white"/>
    </visual>
    <collision>
      <geometry>
        <sphere radius="0.02"/>
      </geometry>
    </collision>
    <inertial>
      <origin rpy="0 0 0" xyz="0 0 0"/>
      <mass value="0.01"/>
      <inertia ixx="1.6000000000000001e-06" ixy="0.0" ixz="0.0" iyy="1.6000000000000001e-06" iyz="0.0" izz="1.6000000000000001e-06"/>
    </inertial>
  </link>
  <joint name="caster_wheel_joint2" type="revolute">
    <parent link="chassis"/>
    <child link="caster_wheel2"/>
    <origin xyz="0.475 -0.2225 -0.06749999999999999"/>
    <axis xyz="0 0 1"/>
    <limit effort="100" lower="-1.5707963267948966" upper="1.5707963267948966" velocity="100"/>
    <dynamics damping="21.75" friction="10.48" spring_reference="0" spring_stiffness="{joint_spring_stiffness}"/>
  </joint>
  <link name="caster_wheel2">
    <visual>
      <geometry>
        <sphere radius="0.02"/>
      </geometry>
      <material name="white"/>
    </visual>
    <collision>
      <geometry>
        <sphere radius="0.02"/>
      </geometry>
    </collision>
    <inertial>
      <origin rpy="0 0 0" xyz="0 0 0"/>
      <mass value="0.01"/>
      <inertia ixx="1.6000000000000001e-06" ixy="0.0" ixz="0.0" iyy="1.6000000000000001e-06" iyz="0.0" izz="1.6000000000000001e-06"/>
    </inertial>
  </link>
  <joint name="robot_joint0" type="fixed">
    <origin rpy="0 0 0.0" xyz="0.3 -0.1 0.72"/>
    <parent link="chassis"/>
    <child link="robot_link0"/>
  </joint>
  <link name="robot_link0">
    <inertial>
      <origin rpy="0 0 0" xyz="0 0 0.031"/>
      <mass value="0.001246584"/>
      <inertia ixx="2.3938568079999997e-06" ixy="0.0" ixz="0.0" iyy="2.3938568079999997e-06" iyz="0.0" izz="3.9890688e-06"/>
    </inertial>
    <visual>
      <origin rpy="0 0 0" xyz="0 0 0.031"/>
      <geometry>
        <cylinder length="0.062" radius="0.08"/>
      </geometry>
      <material name="">
        <color rgba="0.75294 0.75294 0.75294 1"/>
      </material>
    </visual>
    <collision>
      <origin rpy="0 0 0" xyz="0 0 0.031"/>
      <geometry>
        <cylinder length="0.062" radius="0.08"/>
      </geometry>
    </collision>
  </link>
  <joint name="robot_joint1" type="revolute">
    <origin rpy="0 0 0" xyz="0 0 0.062"/>
    <parent link="robot_link0"/>
    <child link="robot_link1"/>
    <axis xyz="0 0 1"/>
    <limit effort="100" lower="-1.5707963267948966" upper="1.5707963267948966" velocity="100"/>
    <dynamics damping="0.01" friction="0.01" spring_reference="0" spring_stiffness="{joint_spring_stiffness}"/>
  </joint>
  <link name="robot_link1">
    <inertial>
      <origin rpy="0 0 0" xyz="0 0 0.08275"/>
      <mass value="0.003327575"/>
      <inertia ixx="1.2919379261979165e-05" ixy="0.0" ixz="0.0" iyy="1.2919379261979165e-05" iyz="0.0" izz="1.064824e-05"/>
    </inertial>
    <visual>
      <origin rpy="0 0 0" xyz="0 0 0.08275"/>
      <geometry>
        <cylinder length="0.1655" radius="0.08"/>
      </geometry>
      <material name="">
        <color rgba="0.75294 0.75294 0.75294 1"/>
      </material>
    </visual>
    <collision>
      <origin rpy="0 0 0" xyz="0 0 0.08275"/>
      <geometry>
        <cylinder length="0.1655" radius="0.08"/>
      </geometry>
    </collision>
  </link>
  <link name="robot_link2">
    <inertial>
      <origin rpy="0 0 0" xyz="0 0 0.1101"/>
      <mass value="0.003989399"/>
      <inertia ixx="2.214289318956667e-05" ixy="0.0" ixz="0.0" iyy="2.214289318956667e-05" iyz="0.0" izz="1.2046096664473334e-05"/>
    </inertial>
    <visual>
      <origin rpy="0 0 0" xyz="0 0 0.1101"/>
      <geometry>
        <box size="0.1346 0.1346 0.2202"/>
      </geometry>
      <material name="">
        <color rgba="0.75294 0.75294 0.75294 1"/>
      </material>
    </visual>
    <collision>
      <origin rpy="0 0 0" xyz="0 0 0.1101"/>
      <geometry>
        <box size="0.1346 0.1346 0.2202"/>
      </geometry>
    </collision>
  </link>
  <joint name="robot_joint2" type="revolute">
    <origin rpy="0 0 0" xyz="0 0 0.1655"/>
    <parent link="robot_link1"/>
    <child link="robot_link2"/>
    <axis xyz="1 0 0"/>
    <limit effort="5" lower="-1.570796327" upper="1.570796327" velocity="1"/>
    <dynamics damping="0.01" friction="0.01" spring_reference="0" spring_stiffness="{joint_spring_stiffness}"/>
  </joint>
  <link name="robot_link3">
    <inertial>
      <origin rpy="0 0 0" xyz="0 0 0.06495"/>
      <mass value="0.000957623"/>
      <inertia ixx="2.0667906377691666e-06" ixy="0.0" ixz="0.0" iyy="1.8271263295591664e-06" iyz="0.0" izz="1.2007602876233333e-06"/>
    </inertial>
    <visual>
      <origin rpy="0 0 0" xyz="0 0 0.06495"/>
      <geometry>
        <box size="0.0776 0.095 0.1299"/>
      </geometry>
      <material name="">
        <color rgba="0.75294 0.75294 0.75294 1"/>
      </material>
    </visual>
    <collision>
      <origin rpy="0 0 0" xyz="0 0 0.06495"/>
      <geometry>
        <box size="0.0776 0.095 0.1299"/>
      </geometry>
    </collision>
  </link>
  <joint name="robot_joint3" type="revolute">
    <origin rpy="0 0 0" xyz="0 0 0.2202"/>
    <parent link="robot_link2"/>
    <child link="robot_link3"/>
    <axis xyz="1 0 0"/>
    <limit effort="5" lower="-1.65" upper="1.65" velocity="1"/>
    <dynamics damping="0.01" friction="0.01" spring_reference="0" spring_stiffness="{joint_spring_stiffness}"/>
  </joint>
  <link name="robot_link4">
    <inertial>
      <origin rpy="0 0 0" xyz="0 0 0.04745"/>
      <mass value="0.000607957"/>
      <inertia ixx="8.584768277283333e-07" ixy="0.0" ixz="0.0" iyy="7.181806173616666e-07" iyz="0.0" izz="6.641129748283332e-07"/>
    </inertial>
    <visual>
      <origin rpy="0 0 0" xyz="0 0 0.04745"/>
      <geometry>
        <box size="0.0719 0.0891 0.0949"/>
      </geometry>
      <material name="">
        <color rgba="0.29412 0.29412 0.29412 1"/>
      </material>
    </visual>
    <collision>
      <origin rpy="0 0 0" xyz="0 0 0.04745"/>
      <geometry>
        <box size="0.0719 0.0891 0.0949"/>
      </geometry>
    </collision>
  </link>
  <joint name="robot_joint4" type="revolute">
    <origin rpy="0 0 0" xyz="0 0 0.1299"/>
    <parent link="robot_link3"/>
    <child link="robot_link4"/>
    <axis xyz="0 0 1"/>
    <limit effort="5" lower="-3.14" upper="3.14" velocity="1"/>
    <dynamics damping="0.01" friction="0.01" spring_reference="0" spring_stiffness="{joint_spring_stiffness}"/>
  </joint>
  <link name="robot_link5">
    <inertial>
      <origin rpy="0 0 0" xyz="0 0 0.0255"/>
      <mass value="0.00017136"/>
      <inertia ixx="1.0711428000000001e-07" ixy="0.0" ixz="0.0" iyy="7.00434e-08" iyz="0.0" izz="1.0287312000000001e-07"/>
    </inertial>
    <visual>
      <origin rpy="0 0 0" xyz="0 0 0.0255"/>
      <geometry>
        <box size="0.048 0.07 0.051"/>
      </geometry>
      <material name="">
        <color rgba="0.79216 0.81961 0.93333 1"/>
      </material>
    </visual>
    <collision>
      <origin rpy="0 0 0" xyz="0 0 0.0255"/>
      <geometry>
        <box size="0.048 0.07 0.051"/>
      </geometry>
    </collision>
  </link>
  <joint name="robot_joint5" type="revolute">
    <origin rpy="0 0 0" xyz="0 0 0.0949"/>
    <parent link="robot_link4"/>
    <child link="robot_link5"/>
    <axis xyz="1 0 0"/>
    <limit effort="5" lower="-1.570796327" upper="1.570796327" velocity="1"/>
    <dynamics damping="0.01" friction="0.01" spring_reference="0" spring_stiffness="{joint_spring_stiffness}"/>
  </joint>
  <link name="robot_link6"/>
  <joint name="robot_joint6" type="revolute">
    <origin rpy="0 0 0" xyz="0 0 0.051"/>
    <parent link="robot_link5"/>
    <child link="robot_link6"/>
    <axis xyz="0 0 1"/>
    <limit effort="5" lower="-3" upper="3" velocity="1"/>
    <dynamics damping="0.01" friction="0.01" spring_reference="0" spring_stiffness="{joint_spring_stiffness}"/>
  </joint>
  <link name="robot_link7"/>
  <joint name="robot_joint7" type="fixed">
    <origin rpy="0 0 0" xyz="0 0 0"/>
    <parent link="robot_link6"/>
    <child link="robot_link7"/>
    <axis xyz="0 0 0"/>
  </joint>
  <link name="robot_hand">
    <inertial>
      <origin rpy="0 0 0" xyz="0 0 0.0245"/>
      <mass value="0.000151743"/>
      <inertia ixx="8.086940861000001e-08" ixy="0.0" ixz="0.0" iyy="6.07224905e-08" iyz="0.0" izz="8.086940861000001e-08"/>
    </inertial>
    <visual>
      <origin rpy="0 0 0" xyz="0 0 0.0245"/>
      <geometry>
        <box size="0.049 0.0632 0.049"/>
      </geometry>
      <material name="">
        <color rgba="0.79216 0.81961 0.93333 1"/>
      </material>
    </visual>
    <collision>
      <origin rpy="0 0 0" xyz="0 0 0.0245"/>
      <geometry>
        <box size="0.049 0.0632 0.049"/>
      </geometry>
    </collision>
  </link>
  <joint name="robot_hand_joint" type="fixed">
    <origin rpy="0 0 1.570796327" xyz="0 0 0"/>
    <parent link="robot_link7"/>
    <child link="robot_hand"/>
  </joint>
  <link name="robot_camera"/>
  <joint name="robot_camera_joint" type="fixed">
    <origin rpy="0 0 1.570796327" xyz="0.0645 0 0.0685"/>
    <parent link="robot_hand"/>
    <child link="robot_camera"/>
    <axis xyz="0 0 0"/>
  </joint>
  <link name="Gripper_Servo_Gear">
    <!-- <xacro:inertial_box mass="0.000001436" x="${gripper_servo_gear_width}" y="${gripper_servo_gear_length}" z="${gripper_servo_gear_height}">
        <origin xyz="0 0 ${gripper_servo_gear_height/2}" rpy="0 0 0"/>
    </xacro:inertial_box> -->
    <inertial>
      <origin rpy="0 0 0" xyz="0.0 0.0 0.01995"/>
      <mass value="0.000476207785199474"/>
      <inertia ixx="0.001" ixy="0" ixz="0" iyy="0.001" iyz="0" izz="0.001"/>
    </inertial>
    <visual>
      <origin rpy="0 0 0" xyz="0 0 0.01995"/>
      <geometry>
        <box size="0.006 0.006 0.0399"/>
      </geometry>
      <material name="">
        <color rgba="0.9098 0.44314 0.031373 1"/>
      </material>
    </visual>
    <collision>
      <origin rpy="0 0 0" xyz="0 0 0.01995"/>
      <geometry>
        <box size="0.006 0.006 0.0399"/>
      </geometry>
    </collision>
  </link>
  <joint name="robot_finger_joint1" type="revolute">
    <origin rpy="0.0 0.0 0.0" xyz="0 0.014 0.022"/>
    <parent link="robot_hand"/>
    <child link="Gripper_Servo_Gear"/>
    <axis xyz="1 0 0"/>
    <limit effort="5.0" lower="-1.5" upper="1.5" velocity="1.0"/>
    <dynamics damping="0.01" friction="0.01" spring_reference="0" spring_stiffness="{gripper_joint_spring_stiffness}"/>
  </joint>
  <link name="robot_rightfinger">
    <!-- <xacro:inertial_box mass="0.00002646" x="${tip_gripper_servo_width}" y="${tip_gripper_servo_length}" z="${tip_gripper_servo_height}">
        <origin xyz="0 0.003 ${tip_gripper_servo_height/2.0}" rpy="0 0 0"/>
    </xacro:inertial_box> -->
    <inertial>
      <origin rpy="0 0 0" xyz="0.0 0.003 0.035"/>
      <mass value="0.000476207785199474"/>
      <inertia ixx="0.001" ixy="0" ixz="0" iyy="0.001" iyz="0" izz="0.001"/>
    </inertial>
    <visual>
      <origin rpy="0 0 0" xyz="0 -0.003 0.035"/>
      <geometry>
        <box size="0.018 0.021 0.07"/>
      </geometry>
      <material name="">
        <color rgba="0 1 0 1"/>
      </material>
    </visual>
    <collision>
      <origin rpy="0 0 0" xyz="0 -0.003 0.035"/>
      <geometry>
        <box size="0.018 0.021 0.07"/>
      </geometry>
    </collision>
  </link>
  <joint name="Tip_Gripper_Servo_Joint" type="revolute">
    <origin rpy="0 0 0" xyz="0 0 0.04"/>
    <parent link="Gripper_Servo_Gear"/>
    <child link="robot_rightfinger"/>
    <axis xyz="1 0 0"/>
    <limit effort="5.0" lower="-1.5" upper="1.5" velocity="1.0"/>
    <dynamics damping="0.01" friction="0.01" spring_reference="0" spring_stiffness="{gripper_joint_spring_stiffness}"/>
  </joint>
  <link name="Gripper_Idol_Gear">
    <!-- <xacro:inertial_box mass="0.000001436" x="${gripper_idol_gear_width}" y="${gripper_idol_gear_length}" z="${gripper_idol_gear_height}">
        <origin xyz="0 0.0 ${gripper_idol_gear_height/2.0}" rpy="0 0 0"/>
    </xacro:inertial_box> -->
    <inertial>
      <origin rpy="0 0 0" xyz="0.0 0.0 0.01995"/>
      <mass value="0.000476207785199481"/>
      <inertia ixx="0.001" ixy="0" ixz="0" iyy="0.001" iyz="0" izz="0.001"/>
    </inertial>
    <visual>
      <origin rpy="0 0 0" xyz="0 0 0.01995"/>
      <geometry>
        <box size="0.006 0.006 0.0399"/>
      </geometry>
      <material name="">
        <color rgba="0.058824 0.64706 1 1"/>
      </material>
    </visual>
    <collision>
      <origin rpy="0 0 0" xyz="0 0 0.01995"/>
      <geometry>
        <box size="0.006 0.006 0.0399"/>
      </geometry>
    </collision>
  </link>
  <joint name="robot_finger_joint2" type="revolute">
    <origin rpy="0.0 0.0 0.0" xyz="0 -0.014 0.022"/>
    <parent link="robot_hand"/>
    <child link="Gripper_Idol_Gear"/>
    <axis xyz="1 0 0"/>
    <limit effort="5.0" lower="-1.5" upper="1.5" velocity="1.0"/>
    <dynamics damping="0.01" friction="0.01" spring_reference="0" spring_stiffness="{gripper_joint_spring_stiffness}"/>
  </joint>
  <link name="robot_leftfinger">
    <!-- <xacro:inertial_box mass="0.00002646" x="${tip_gripper_idol_width}" y="${tip_gripper_idol_length}" z="${tip_gripper_idol_height}">
        <origin xyz="0 0.0 ${tip_gripper_idol_height/2.0}" rpy="0 0 0"/>
    </xacro:inertial_box> -->
    <inertial>
      <origin rpy="0 0 0" xyz="0.0 0.003 0.035"/>
      <mass value="0.000476207785199481"/>
      <inertia ixx="0.001" ixy="0" ixz="0" iyy="0.001" iyz="0" izz="0.001"/>
    </inertial>
    <visual>
      <origin rpy="0 0 0" xyz="0 0.003 0.035"/>
      <geometry>
        <box size="0.018 0.021 0.07"/>
      </geometry>
      <material name="">
        <color rgba="1 0 0 1"/>
      </material>
    </visual>
    <collision>
      <origin rpy="0 0 0" xyz="0 0.003 0.035"/>
      <geometry>
        <box size="0.018 0.021 0.07"/>
      </geometry>
    </collision>
  </link>
  <joint name="Tip_Gripper_Idol_Joint" type="revolute">
    <origin rpy="0 0 0" xyz="0 0 0.04"/>
    <parent link="Gripper_Idol_Gear"/>
    <child link="robot_leftfinger"/>
    <axis xyz="1 0 0"/>
    <limit effort="5.0" lower="-1.5" upper="1.5" velocity="1.0"/>
    <dynamics damping="0.01" friction="0.01" spring_reference="0" spring_stiffness="{gripper_joint_spring_stiffness}"/>
  </joint>
  <!-- <xacro:include filename="lidar.xacro" />
    <xacro:include filename="face.xacro" /> -->
  <!-- <xacro:include filename="ros2_control.xacro" /> -->
  <!-- <xacro:if value="$(arg use_ros2_control)">
        <xacro:include filename="ros2_control.xacro" />
    </xacro:if>
    <xacro:unless value="$(arg use_ros2_control)">
        <xacro:include filename="gazebo_control.xacro" />
    </xacro:unless>
    <xacro:include filename="lidar.xacro" /> -->
  <!-- <xacro:include filename="camera.xacro" /> -->
  <!-- <xacro:include filename="depth_camera.xacro" /> -->
  <!-- <xacro:include filename="face.xacro" /> -->
  <gazebo>
    <!-- Odometry Publisher -->
    <plugin filename="ignition-gazebo-odometry-publisher-system" name="ignition::gazebo::systems::OdometryPublisher">
      <odom_publish_frequency>50</odom_publish_frequency>
      <odom_topic>/odom</odom_topic>
      <odom_frame>odom</odom_frame>
      <robot_base_frame>base_link</robot_base_frame>
      <dimensions>3</dimensions>
    </plugin>
    <!-- Joint States -->
    <plugin filename="libignition-gazebo-joint-state-publisher-system.so" name="ignition::gazebo::systems::JointStatePublisher"/>
    <!-- Diff Drive -->
    <plugin filename="libignition-gazebo-diff-drive-system.so" name="ignition::gazebo::systems::DiffDrive">
      <left_joint>left_wheel_joint</left_joint>
      <right_joint>right_wheel_joint</right_joint>
      <wheel_separation>0.445</wheel_separation>
      <wheel_radius>0.0625</wheel_radius>
      <odom_publish_frequency>0</odom_publish_frequency>
      <topic>cmd_vel</topic>
      <frame_id>odom_diff</frame_id>
      <child_frame_id>base_footprint</child_frame_id>
    </plugin>
    <!-- Joint Trajectories -->
    <plugin filename="libignition-gazebo-joint-trajectory-controller-system.so" name="ignition::gazebo::systems::JointTrajectoryController">
      <topic>joint_trajectory</topic>
      <joint_name>robot_joint1</joint_name>
      <initial_position>0</initial_position>
      <position_p_gain>1.0</position_p_gain>
      <position_d_gain>0.01</position_d_gain>
      <position_i_gain>0.1</position_i_gain>
      <position_i_min>-0.2</position_i_min>
      <position_i_max>0.2</position_i_max>
      <position_cmd_min>-100</position_cmd_min>
      <position_cmd_max>100</position_cmd_max>
      <joint_name>robot_joint2</joint_name>
      <initial_position>0</initial_position>
      <position_p_gain>1.0</position_p_gain>
      <position_d_gain>0.01</position_d_gain>
      <position_i_gain>0.1</position_i_gain>
      <position_i_min>-0.2</position_i_min>
      <position_i_max>0.2</position_i_max>
      <position_cmd_min>-100</position_cmd_min>
      <position_cmd_max>100</position_cmd_max>
      <joint_name>robot_joint3</joint_name>
      <initial_position>0</initial_position>
      <position_p_gain>1.0</position_p_gain>
      <position_d_gain>0.01</position_d_gain>
      <position_i_gain>0.1</position_i_gain>
      <position_i_min>-0.2</position_i_min>
      <position_i_max>0.2</position_i_max>
      <position_cmd_min>-100</position_cmd_min>
      <position_cmd_max>100</position_cmd_max>
      <joint_name>robot_joint4</joint_name>
      <initial_position>0</initial_position>
      <position_p_gain>1.0</position_p_gain>
      <position_d_gain>0.01</position_d_gain>
      <position_i_gain>0.1</position_i_gain>
      <position_i_min>-0.2</position_i_min>
      <position_i_max>0.2</position_i_max>
      <position_cmd_min>-100</position_cmd_min>
      <position_cmd_max>100</position_cmd_max>
      <joint_name>robot_joint5</joint_name>
      <initial_position>0</initial_position>
      <position_p_gain>1.0</position_p_gain>
      <position_d_gain>0.01</position_d_gain>
      <position_i_gain>0.1</position_i_gain>
      <position_i_min>-0.2</position_i_min>
      <position_i_max>0.2</position_i_max>
      <position_cmd_min>-100</position_cmd_min>
      <position_cmd_max>100</position_cmd_max>
      <joint_name>robot_joint6</joint_name>
      <initial_position>0</initial_position>
      <position_p_gain>1.0</position_p_gain>
      <position_d_gain>0.01</position_d_gain>
      <position_i_gain>0.1</position_i_gain>
      <position_i_min>-0.2</position_i_min>
      <position_i_max>0.2</position_i_max>
      <position_cmd_min>-100</position_cmd_min>
      <position_cmd_max>100</position_cmd_max>
      <joint_name>robot_finger_joint1</joint_name>
      <initial_position>0</initial_position>
      <position_p_gain>1.0</position_p_gain>
      <position_d_gain>0.01</position_d_gain>
      <position_i_gain>0.1</position_i_gain>
      <position_i_min>-0.2</position_i_min>
      <position_i_max>0.2</position_i_max>
      <position_cmd_min>-100</position_cmd_min>
      <position_cmd_max>100</position_cmd_max>
      <joint_name>robot_finger_joint2</joint_name>
      <initial_position>0</initial_position>
      <position_p_gain>1.0</position_p_gain>
      <position_d_gain>0.01</position_d_gain>
      <position_i_gain>0.1</position_i_gain>
      <position_i_min>-0.2</position_i_min>
      <position_i_max>0.2</position_i_max>
      <position_cmd_min>-100</position_cmd_min>
      <position_cmd_max>100</position_cmd_max>
      <joint_name>Tip_Gripper_Servo_Joint</joint_name>
      <initial_position>0</initial_position>
      <position_p_gain>1.0</position_p_gain>
      <position_d_gain>0.01</position_d_gain>
      <position_i_gain>0.1</position_i_gain>
      <position_i_min>-0.2</position_i_min>
      <position_i_max>0.2</position_i_max>
      <position_cmd_min>-100</position_cmd_min>
      <position_cmd_max>100</position_cmd_max>
      <joint_name>Tip_Gripper_Idol_Joint</joint_name>
      <initial_position>0</initial_position>
      <position_p_gain>1.0</position_p_gain>
      <position_d_gain>0.01</position_d_gain>
      <position_i_gain>0.1</position_i_gain>
      <position_i_min>-0.2</position_i_min>
      <position_i_max>0.2</position_i_max>
      <position_cmd_min>-100</position_cmd_min>
      <position_cmd_max>100</position_cmd_max>
    </plugin>
  </gazebo>
</robot>
